Workbook

Sheet Worksheet
A1: SKU | B1: Produto | C1: Localização | D1: Un | E1: Quantidade | F1: Valor unitário | G1: Valor total | H1: ID_MercadoLivre
A2: 814 | B2: EXTENSOR APLICADOR DE LIMPA AR CONDICIONADO | D2: UN | E2: 0 | F2: 0 | G2: 0 | H2: =VLOOKUP(A2,[1]Anúncios!E$7:AB$3595,24,FALSE) -> #N/A
A3: 2092 | B3: JUNTA TAMPA VALVULA FORD DURATEC 2.0 FOCUS/RANGER/ECOSPORT | D3: UN | E3: 0 | F3: 58 | G3: 0 | H3: =VLOOKUP(A3,[1]Anúncios!E$7:AB$3595,24,FALSE) -> #N/A
A4: 3982 | B4: SENSOR DE TEMPERATURA EXTERNO VW GOL/POLO/AMAROK/GOLF/FOX/JETTA 04/20 | C4: PL-E | D4: UN | E4: 5 | F4: 35 | G4: 175 | H4: =VLOOKUP(A4,[1]Anúncios!E$7:AB$3595,24,FALSE) -> MLB6594730068
A5: 5101 | B5: KIT PALHETA COMPRESSOR DENSO 6SEL16C PEUGEOT CITROEN | C5: Ie2 | D5: KIT | E5: 5 | F5: 0 | G5: 0 | H5: =VLOOKUP(A5,[1]Anúncios!E$7:AB$3595,24,FALSE) -> #N/A
A6: 5102 | B6: KIT PALHETA COMPRESSOR COMPRESSORA DENSO 6P148 NEW HOLLAND VW FIAT | C6: Ie2 | D6: KIT | E6: 1 | F6: 0 | G6: 0 | H6: =VLOOKUP(A6,[1]Anúncios!E$7:AB$3595,24,FALSE) -> #N/A
A7: 5103 | B7: KIT PALHETA COMPRESSORA DENSO VW AMAROK | C7: Ie2 | D7: KIT | E7: 1 | F7: 0 | G7: 0 | H7: =VLOOKUP(A7,[1]Anúncios!E$7:AB$3595,24,FALSE) -> #N/A
A8: 5104 | B8: KIT PALETA COMPRESSORA DENSO 7SEU17C VW MERCEDES LAND ROVER PORSHE | D8: KIT | E8: 1 | F8: 0 | G8: 0 | H8: =VLOOKUP(A8,[1]Anúncios!E$7:AB$3595,24,FALSE) -> #N/A
A9: 5105 | B9: KIT PALHETA COMPRESSORA DENSO VW GOLF AUDI | C9: Ie2 | D9: KIT | E9: 1 | F9: 0 | G9: 0 | H9: =VLOOKUP(A9,[1]Anúncios!E$7:AB$3595,24,FALSE) -> #N/A
A10: 5106 | B10: KIT PALHETA COMPRESSOR DENSO PALIO | C10: Ie2 | D10: KIT | E10: 1 | F10: 0 | G10: 0 | H10: =VLOOKUP(A10,[1]Anúncios!E$7:AB$3595,24,FALSE) -> #N/A
A11: 5201 | B11: KIT PALHETA COMPRESSORA SANDEN HS15 FORD HYUNDAI | C11: Ie2 | D11: KIT | E11: 1 | F11: 0 | G11: 0 | H11: =VLOOKUP(A11,[1]Anúncios!E$7:AB$3595,24,FALSE) -> #N/A
A12: 5202 | B12: KIT PALHETA COMPRESSORA SANDEN FOECOO1 FORD | C12: Ie2 | D12: KIT | E12: 1 | F12: 0 | G12: 0 | H12: =VLOOKUP(A12,[1]Anúncios!E$7:AB$3595,24,FALSE) -> #N/A
A13: 5203 | B13: KIT PALHETA COMPRESSORA SANDEN VW AUDI | C13: Ie2 | D13: KIT | E13: 1 | F13: 0 | G13: 0 | H13: =VLOOKUP(A13,[1]Anúncios!E$7:AB$3595,24,FALSE) -> #N/A
A14: 5204 | B14: KIT PALHETA COMPRESSORA SANDEN 5H14 UNIVERSAL SCANIA | C14: Ie2 | D14: KIT | E14: 1 | F14: 0 | G14: 0 | H14: =VLOOKUP(A14,[1]Anúncios!E$7:AB$3595,24,FALSE) -> #N/A
A15: 5205 | B15: KIT PALHETA COMPRESSORA SANDEN 7H15 VOLVO CARTEPILLAR NEW HOLLAND CASE MAGNUM UNIVERSAL | C15: Ie2 | D15: KIT | E15: 1 | F15: 0 | G15: 0 | H15: =VLOOKUP(A15,[1]Anúncios!E$7:AB$3595,24,FALSE) -> #N/A
A16: 5206 | B16: KIT PALHETA COMPRESSORA SANDEN 7H16 AUDI | C16: Ie2 | D16: KIT | E16: 1 | F16: 0 | G16: 0 | H16: =VLOOKUP(A16,[1]Anúncios!E$7:AB$3595,24,FALSE) -> #N/A
A17: 5207 | B17: KIT PALHETA COMPRESSORA SANDEN SD7V16 AUDI VW RENAULT FIAT | C17: Ie2 | D17: KIT | E17: 5 | F17: 0 | G17: 0 | H17: =VLOOKUP(A17,[1]Anúncios!E$7:AB$3595,24,FALSE) -> #N/A
A18: 5208 | B18: KIT PALHETA COMPRESSORA SANDEN AUDI VW | C18: Ie2 | D18: KIT | E18: 1 | F18: 0 | G18: 0 | H18: =VLOOKUP(A18,[1]Anúncios!E$7:AB$3595,24,FALSE) -> #N/A
A19: 5209 | B19: KIT PALHETA COMPRESSORA SANDEN 7H15 JOHN DEERE CITROEN FIAT PEUGEOT VOLVO | C19: Ie2 | D19: KIT | E19: 1 | F19: 0 | G19: 0 | H19: =VLOOKUP(A19,[1]Anúncios!E$7:AB$3595,24,FALSE) -> #N/A
A20: 5210 | B20: KIT PALHETA COMPRESSORA SANDEN VW | C20: Ie2 | D20: KIT | E20: 1 | F20: 0 | G20: 0 | H20: =VLOOKUP(A20,[1]Anúncios!E$7:AB$3595,24,FALSE) -> #N/A
... A39: 250008 | B39: ROLAMENTO DENSO SANDEN RENAULT / PEUGEOT/ CITROEN / TM21 / ZEXEL CORSA CELTA / HONDA FIT 2008 (35X55X20) | C39: Bd44 | D39: UN | E39: 0 | F39: 25 | G39: 0 | H39: =VLOOKUP(A39,[1]Anúncios!E$7:AB$3595,24,FALSE) -> #N/A
A40: 255242 | B40: Rolamento Roda Traseira Peugeot 208 Citroen C3,ds3 Após 2012 | D40: UN | E40: 0 | F40: 0 | G40: 0 | H40: =VLOOKUP(A40,[1]Anúncios!E$7:AB$3595,24,FALSE) -> #N/A
A41: 450113 | B41: EMENDA 06MM ALUMINIO S/CLIP UNIDADE | C41: De23 | D41: UN | E41: 0 | F41: 1.82 | G41: 0 | H41: =VLOOKUP(A41,[1]Anúncios!E$7:AB$3595,24,FALSE) -> #N/A
A42: 450554 | B42: CANECA CLIP ALUMINIO 06MM PCT C/ 10 PÇS | C42: Cd44 Cd62 | D42: PCT | E42: 0 | F42: 0 | G42: 0 | H42: =VLOOKUP(A42,[1]Anúncios!E$7:AB$3595,24,FALSE) -> #N/A
A43: 460053 | B43: VALVULA TORRE COMPRESSOR SANDEN PXE14 / DELPHI NISSAN SENTRA 2013 > | C43: Cd23 / BF Ad7 | D43: UN | E43: 0 | F43: 167 | G43: 0 | H43: =VLOOKUP(A43,[1]Anúncios!E$7:AB$3595,24,FALSE) -> #N/A
A44: 503196 | B44: BOMBA ALTA PRESSAO VW UP GOLF JETTA POLO VIRTUS | D44: UN | E44: 0 | F44: 1200 | G44: 0 | H44: =VLOOKUP(A44,[1]Anúncios!E$7:AB$3595,24,FALSE) -> #N/A
A45: 503451 | B45: Sensor PressÃo Servo Freio Fiat Toro Jeep Renegade Diesel | C45: Hd1 | D45: UN | E45: 2 | F45: 25 | G45: 50 | H45: =VLOOKUP(A45,[1]Anúncios!E$7:AB$3595,24,FALSE) -> MLB5731328920
A46: 503877 | B46: CONJUNTO HELICE+POLIA VISCOSA GMS10 TRAILBLAZER 2.8 17 A 20121 | D46: UN | E46: 0 | F46: 870 | G46: 0 | H46: =VLOOKUP(A46,[1]Anúncios!E$7:AB$3595,24,FALSE) -> #N/A
A47: 504139 | B47: RESISTENCIA VENTILADOR INTERNO GM MONTANA AGILE PALIO UNO 4 VELOCIDADES | C47: Id19 | D47: UN | E47: 2 | F47: 0 | G47: 0 | H47: =VLOOKUP(A47,[1]Anúncios!E$7:AB$3595,24,FALSE) -> MLB4277202085
A48: 504182 | B48: Sensor Map Vw Golf Polo Virtus Up 1.0 Tsi 04e906051k | C48: PL-A | D48: UN | E48: 5 | F48: 45 | G48: 225 | H48: =VLOOKUP(A48,[1]Anúncios!E$7:AB$3595,24,FALSE) -> MLB6594535846
A49: 504254 | B49: Sensor Nivel Boia Combustivel Hyundai Tucson 2012 Em Diante BOSCH | C49: O3 | D49: UN | E49: 0 | F49: 19 | G49: 0 | H49: =VLOOKUP(A49,[1]Anúncios!E$7:AB$3595,24,FALSE) -> #N/A
A50: 504540 | B50: Sensor Map Intercooler Ar GM Onix Tracker Turbo 2020 Em Diante | C50: PL-E | D50: UN | E50: 5 | F50: 45 | G50: 225 | H50: =VLOOKUP(A50,[1]Anúncios!E$7:AB$3595,24,FALSE) -> MLB6594546582
A51: 504678 | B51: KIT JUNTA TAMPA DIAFRAGMA MOBI ARGO NOVO UNO 1.0 3CC FIRFLAY | C51: Hd2 | D51: UN | E51: 1 | F51: 0 | G51: 0 | H51: =VLOOKUP(A51,[1]Anúncios!E$7:AB$3595,24,FALSE) -> #N/A
A52: 504679 | B52: KIT Junta Tampa De Valvulas DIAFRAGMA FIAT ARGO 1.3 4CC 2020 | C52: Hd1 | D52: UN | E52: 1 | F52: 0 | G52: 0 | H52: =VLOOKUP(A52,[1]Anúncios!E$7:AB$3595,24,FALSE) -> #N/A
A53: 504683 | B53: KIT JUNTA TAMPA DIAFRAAGMA VW JETTA GOLF PASSAT | D53: UN | E53: 0 | F53: 0 | G53: 0 | H53: =VLOOKUP(A53,[1]Anúncios!E$7:AB$3595,24,FALSE) -> #N/A
A54: 504687 | B54: Junta Tampa De Valvula New Fiesta 1.6 Sigma 16v 2014 A 2018 | C54: Hd1 | D54: UN | E54: 1 | F54: 35 | G54: 35 | H54: =VLOOKUP(A54,[1]Anúncios!E$7:AB$3595,24,FALSE) -> MLB5373872976
A55: 504691 | B55: Junta Tampa De Valvulas GM S10 ASTRA VECTRA KADETT ZAFIRA BLAZER | D55: UN | E55: 0 | F55: 0 | G55: 0 | H55: =VLOOKUP(A55,[1]Anúncios!E$7:AB$3595,24,FALSE) -> #N/A
A56: 504694 | B56: KIT Junta Tampa De VAlvulas DIAFRAGMA GM ONIX 2012 A 2015 TRACKER 2013 CRUZE 2011 | D56: UN | E56: 0 | F56: 0 | G56: 0 | H56: =VLOOKUP(A56,[1]Anúncios!E$7:AB$3595,24,FALSE) -> #N/A
A57: 504695 | B57: Kit Junta Vedacao Bomba Dagua VW Gol Voyage Fox Up Polo Virtus | D57: UN | E57: 0 | F57: 29.9 | G57: 0 | H57: =VLOOKUP(A57,[1]Anúncios!E$7:AB$3595,24,FALSE) -> #N/A
A58: 504696 | B58: Junta Tampa De valvulas DIAFRAGMA GM ONIX 2012 A 2015 TRACKER 2013 CRUZE 2011 | D58: UN | E58: 0 | F58: 0 | G58: 0 | H58: =VLOOKUP(A58,[1]Anúncios!E$7:AB$3595,24,FALSE) -> #N/A
...
